Workbook

Sheet Cover
B2: LAST-MILE DELIVERY SERVICE 3-YEAR FINANCIAL MODEL
B3: Last-Mile Delivery Operation · Qatar · Base Case Build, 2026
B5: OVERVIEW
B6: Bottom-up 3-year financial model for a last-mile delivery operation. Starts from the Qatar e-commerce parcel market (TAM → SAM → Merchant Accounts → Parcels/Month) and builds to a monthly P&L and EBITDA. Yellow-highlighted cells are analyst estimates — adjust them to stress-test the model.
B8: NAVIGATE THE MODEL
B9: 1 · Assumptions All inputs — market data, pricing, driver mix, cost rates. Yellow = analyst estimate.
B10: 2 · Volume & Funnel Monthly parcel volume for 36 months — merchant ramp, parcels per merchant, zone split.
B11: 3 · Monthly P&L Three revenue streams, cost of delivery, opex — monthly detail plus FY1–3 totals.
B12: 4 · Annual Summary 3-year P&L rollup, revenue mix, driver model comparison, funding requirement.
B14: COLOUR LEGEND
B15: Blue text → Given input (market data or published rate)
B16: Blue text + yellow background → Analyst estimate — change to stress-test
... B18: Green text → Link pulling from another tab — do not overwrite

Sheet Assumptions
A1: LAST-MILE DELIVERY SERVICE | MODEL ASSUMPTIONS
A2: Blue = given (market data / published). Yellow = analyst estimate — change to stress-test. Black = formula, do not edit.
A4: MARKET CONTEXT — QATAR E-COMMERCE PARCELS
A5: Qatar resident population (2026) | B5: 3300000 | E5: How many people live in Qatar right now?
A6: Active online shoppers — Qatar (2026 est.) | B6: 1600000 | E6: How many of them shop online at least once a month?
A7: Average orders per shopper per year | B7: 18 | E7: On average, how many orders does each shopper place per year?
A8: Gross parcel volume — Qatar per year | B8: 28800000 | E8: Total parcels needing delivery across Qatar per year. (shoppers × orders)
A9: Mid-value addressable share (SAM %) | B9: 0.38 | E9: What share of the market is realistically ours to compete for? Strips out premium couriers and in-house app delivery.
A10: SAM — addressable parcels per year | B10: =B8*B9 -> 10944000 | E10: Our total addressable parcel pool. (gross volume × addressable share)
A11: SAM — addressable parcels per month | B11: =B10/12 -> 912000 | E11: Same number broken into months. Used as the demand ceiling in the funnel.
A13: MERCHANT ACQUISITION FUNNEL
A14: Merchant accounts — Month 1 seed | B14: 3 | E14: How many merchant accounts do we launch with on Day 1?
A15: Target merchant accounts by year-end | B15: 20 | C15: 80 | D15: 160 | E15: How many merchant accounts do we want signed by end of each year? [Y1 | Y2 | Y3]
A16: Avg parcels per merchant per month | B16: 80 | C16: 110 | D16: 140 | E16: On average, how many parcels does each merchant send through us per month? [Y1 | Y2 | Y3]
A17: Monthly merchant growth rate — derived | B17: =((B15/B14)^(1/11)-1) -> 0.18823077 | C17: =((C15/B15)^(1/12)-1) -> 0.12246205 | D17: =((D15/C15)^(1/12)-1) -> 0.059463094 | E17: Monthly growth rate needed to hit the year-end merchant target. Don't edit — derived from targets above.
A19: PRICING & UNIT ECONOMICS
A20: Zone A — Doha metro delivery fee (QAR/parcel) | B20: 18 | E20: What do we charge per delivery inside the Doha metro corridor?
A21: Zone B — Greater Doha delivery fee (QAR/parcel) | B21: 22 | E21: What do we charge per delivery to outer Doha / Greater Qatar?
A22: Zone A parcels as % of total volume | B22: 0.72 | E22: What share of total deliveries fall inside the Doha metro? (~72% based on e-commerce demand concentration.)
A23: Blended delivery fee — derived (QAR/parcel) | B23: =B20*B22+B21*(1-B22) -> 19.12 | E23: Weighted average fee across both zones. Don't edit — calculated from fees and zone split above.
A24: COD handling fee — % of declared parcel value | B24: 0.015 | E24: What % of parcel value do we charge as a COD handling surcharge?
A25: COD parcels as % of total (Y1→Y3) | B25: 0.35 | C25: 0.28 | D25: 0.22 | E25: What share of deliveries are cash-on-delivery? Declines as digital payments grow. [Y1 | Y2 | Y3]
A26: Avg declared parcel value (QAR) | B26: 180 | E26: What is the typical declared value of a parcel we deliver?
A27: Returns fee (QAR/parcel returned) | B27: 8 | E27: What flat fee do we charge the merchant when a delivery fails or is returned?
A28: Return rate (% of total deliveries) | B28: 0.06 | E28: What % of our deliveries fail or get returned?
A30: DRIVER MODEL — Contracted vs Employed (set either to 0 to run single model)
A31: Total delivery capacity = (Contracted drivers × drops/day × working days) + (Employed drivers × drops/day × working days). Revenue and variable costs flow from total capacity. Set contracted = 0 for fully employed fleet; set employed = 0 for fully contracted.
A32: Working days per month | B32: 26 | E32: How many days per month do drivers work?
A33: Contracted drivers — number (Y1 / Y2 / Y3) | B33: 9 | C33: 18 | D33: 30 | E33: How many contracted (gig) drivers do we use? Set to 0 for fully employed model. [Y1 | Y2 | Y3]
A34: Contracted driver — drops per day | B34: 20 | E34: How many deliveries can one contracted driver complete per day?
A35: Contracted driver — cost per drop (QAR) | B35: 9 | E35: How much do we pay a contracted driver per delivery attempt?
A36: Employed drivers — number (Y1 / Y2 / Y3) | B36: 6 | C36: 12 | D36: 22 | E36: How many salaried drivers do we employ? Set to 0 for fully contracted model. [Y1 | Y2 | Y3]
A37: Employed driver — drops per day | B37: 22 | E37: How many deliveries can one employed driver complete per day? (Slightly higher — fixed shift discipline.)
A38: Employed driver — monthly salary (QAR) | B38: 2800 | E38: What is the monthly all-in salary for an employed driver?
A39: Total monthly capacity — contracted (Y1) | B39: =B33*B34*B32 -> 4680 | E39: Maximum deliveries our contracted drivers can handle per month. Don't edit — calculated.
A40: Total monthly capacity — employed (Y1) | B40: =B36*B37*B32 -> 3432 | E40: Maximum deliveries our employed drivers can handle per month. Don't edit — calculated.
A41: Total monthly capacity — combined (Y1) | B41: =B39+B40 -> 8112 | E41: Total fleet capacity per month. Don't edit — calculated.
A42: Capacity utilisation rate (target) | B42: 0.75 | E42: What % of fleet capacity do we actually fill? 75% is a realistic planning rate.
A43: First-attempt delivery success rate | B43: 0.88 | E43: What % of delivery attempts succeed on the first try? Failed attempts still cost fuel and driver time. (~88% Qatar benchmark.)
A45: OPERATING COST ASSUMPTIONS
...

Sheet Volume & Funnel
A1: LAST-MILE DELIVERY SERVICE | VOLUME & FUNNEL BUILD
A2: SAM 10.9M parcels/yr → Merchant accounts (ramped) → Parcels/month → Deliveries. All figures units (#) unless noted.
B3: YEAR 1 (2026) | O3: YEAR 2 (2027) | AB3: YEAR 3 (2028) | AO3: FY1 Total | AP3: FY2 Total | AQ3: FY3 Total
B4: Y1M1 | C4: Y1M2 | D4: Y1M3 | E4: Y1M4 | F4: Y1M5 | G4: Y1M6 | H4: Y1M7 | I4: Y1M8 | J4: Y1M9 | K4: Y1M10 | L4: Y1M11 | M4: Y1M12 | O4: Y2M1 | P4: Y2M2 | Q4: Y2M3 | R4: Y2M4 | S4: Y2M5 | T4: Y2M6 | U4: Y2M7 | V4: Y2M8 | W4: Y2M9 | X4: Y2M10 | Y4: Y2M11 | Z4: Y2M12 | AB4: Y3M1 | AC4: Y3M2 | AD4: Y3M3 | AE4: Y3M4 | AF4: Y3M5 | AG4: Y3M6 | AH4: Y3M7 | AI4: Y3M8 | AJ4: Y3M9 | AK4: Y3M10 | AL4: Y3M11 | AM4: Y3M12
A5: MERCHANT FUNNEL
A6: Merchant Accounts — cumulative (end of month) | B6: =Assumptions!B14 -> 3 | C6: =B6*(1+Assumptions!B17) -> 3.5646923 | D6: =C6*(1+Assumptions!B17) -> 4.2356771 | E6: =D6*(1+Assumptions!B17) -> 5.0329619 | F6: =E6*(1+Assumptions!B17) -> 5.9803201 | G6: =F6*(1+Assumptions!B17) -> 7.1060004 | H6: =G6*(1+Assumptions!B17) -> 8.4435683 | I6: =H6*(1+Assumptions!B17) -> 10.032908 | J6: =I6*(1+Assumptions!B17) -> 11.92141 | K6: =J6*(1+Assumptions!B17) -> 14.165386 | L6: =K6*(1+Assumptions!B17) -> 16.831747 | M6: =L6*(1+Assumptions!B17) -> 20 | O6: =M6*(1+Assumptions!C17) -> 22.449241 | P6: =O6*(1+Assumptions!C17) -> 25.198421 | Q6: =P6*(1+Assumptions!C17) -> 28.284271 | R6: =Q6*(1+Assumptions!C17) -> 31.748021 | S6: =R6*(1+Assumptions!C17) -> 35.635949 | T6: =S6*(1+Assumptions!C17) -> 40 | U6: =T6*(1+Assumptions!C17) -> 44.898482 | V6: =U6*(1+Assumptions!C17) -> 50.396842 | W6: =V6*(1+Assumptions!C17) -> 56.568542 | X6: =W6*(1+Assumptions!C17) -> 63.496042 | Y6: =X6*(1+Assumptions!C17) -> 71.271897 | Z6: =Y6*(1+Assumptions!C17) -> 80 | AB6: =Z6*(1+Assumptions!D17) -> 84.757048 | AC6: =AB6*(1+Assumptions!D17) -> 89.796964 | AD6: =AC6*(1+Assumptions!D17) -> 95.136569 | AE6: =AD6*(1+Assumptions!D17) -> 100.79368 | AF6: =AE6*(1+Assumptions!D17) -> 106.78719 | AG6: =AF6*(1+Assumptions!D17) -> 113.13708 | AH6: =AG6*(1+Assumptions!D17) -> 119.86457 | AI6: =AH6*(1+Assumptions!D17) -> 126.99208 | AJ6: =AI6*(1+Assumptions!D17) -> 134.54343 | AK6: =AJ6*(1+Assumptions!D17) -> 142.54379 | AL6: =AK6*(1+Assumptions!D17) -> 151.01989 | AM6: =AL6*(1+Assumptions!D17) -> 160 | AO6: =M6 -> 20 | AP6: =Z6 -> 80 | AQ6: =AM6 -> 160
A7: Avg Parcels per Merchant per Month | B7: =Assumptions!B16 -> 80 | C7: =Assumptions!B16 -> 80 | D7: =Assumptions!B16 -> 80 | E7: =Assumptions!B16 -> 80 | F7: =Assumptions!B16 -> 80 | G7: =Assumptions!B16 -> 80 | H7: =Assumptions!B16 -> 80 | I7: =Assumptions!B16 -> 80 | J7: =Assumptions!B16 -> 80 | K7: =Assumptions!B16 -> 80 | L7: =Assumptions!B16 -> 80 | M7: =Assumptions!B16 -> 80 | O7: =Assumptions!C16 -> 110 | P7: =Assumptions!C16 -> 110 | Q7: =Assumptions!C16 -> 110 | R7: =Assumptions!C16 -> 110 | S7: =Assumptions!C16 -> 110 | T7: =Assumptions!C16 -> 110 | U7: =Assumptions!C16 -> 110 | V7: =Assumptions!C16 -> 110 | W7: =Assumptions!C16 -> 110 | X7: =Assumptions!C16 -> 110 | Y7: =Assumptions!C16 -> 110 | Z7: =Assumptions!C16 -> 110 | AB7: =Assumptions!D16 -> 140 | AC7: =Assumptions!D16 -> 140 | AD7: =Assumptions!D16 -> 140 | AE7: =Assumptions!D16 -> 140 | AF7: =Assumptions!D16 -> 140 | AG7: =Assumptions!D16 -> 140 | AH7: =Assumptions!D16 -> 140 | AI7: =Assumptions!D16 -> 140 | AJ7: =Assumptions!D16 -> 140 | AK7: =Assumptions!D16 -> 140 | AL7: =Assumptions!D16 -> 140 | AM7: =Assumptions!D16 -> 140
A8: Total Parcels Demanded / Month (#) | B8: =B6*B7 -> 240 | C8: =C6*C7 -> 285.17538 | D8: =D6*D7 -> 338.85417 | E8: =E6*E7 -> 402.63695 | F8: =F6*F7 -> 478.42561 | G8: =G6*G7 -> 568.48003 | H8: =H6*H7 -> 675.48547 | I8: =I6*I7 -> 802.63262 | ... M8: =M6*M7 -> 1600 | O8: =O6*O7 -> 2469.4165 | P8: =P6*P7 -> 2771.8263 | Q8: =Q6*Q7 -> 3111.2698 | R8: =R6*R7 -> 3492.2823 | S8: =S6*S7 -> 3919.9544 | T8: =T6*T7 -> 4400 | U8: =U6*U7 -> 4938.833 | V8: =V6*V7 -> 5543.6526 | ... Z8: =Z6*Z7 -> 8800 | AB8: =AB6*AB7 -> 11865.987 | AC8: =AC6*AC7 -> 12571.575 | AD8: =AD6*AD7 -> 13319.12 | AE8: =AE6*AE7 -> 14111.116 | AF8: =AF6*AF7 -> 14950.206 | AG8: =AG6*AG7 -> 15839.192 | AH8: =AH6*AH7 -> 16781.039 | AI8: =AI6*AI7 -> 17778.892 | ... AM8: =AM6*AM7 -> 22400 | AO8: =SUM(B8:M8) -> 8825.1736 | AP8: =SUM(O8:Z8) -> 60494.248 | AQ8: =SUM(AB8:AM8) -> 199552.12
A9: Fleet Capacity / Month — Combined (#) | B9: =(Assumptions!B33*Assumptions!B34*Assumptions!B32)+(Assumptions!B36*Assumptions!B37*Assumptions!B32) -> 8112 | C9: =(Assumptions!B33*Assumptions!B34*Assumptions!B32)+(Assumptions!B36*Assumptions!B37*Assumptions!B32) -> 8112 | D9: =(Assumptions!B33*Assumptions!B34*Assumptions!B32)+(Assumptions!B36*Assumptions!B37*Assumptions!B32) -> 8112 | E9: =(Assumptions!B33*Assumptions!B34*Assumptions!B32)+(Assumptions!B36*Assumptions!B37*Assumptions!B32) -> 8112 | F9: =(Assumptions!B33*Assumptions!B34*Assumptions!B32)+(Assumptions!B36*Assumptions!B37*Assumptions!B32) -> 8112 | G9: =(Assumptions!B33*Assumptions!B34*Assumptions!B32)+(Assumptions!B36*Assumptions!B37*Assumptions!B32) -> 8112 | H9: =(Assumptions!B33*Assumptions!B34*Assumptions!B32)+(Assumptions!B36*Assumptions!B37*Assumptions!B32) -> 8112 | I9: =(Assumptions!B33*Assumptions!B34*Assumptions!B32)+(Assumptions!B36*Assumptions!B37*Assumptions!B32) -> 8112 | J9: =(Assumptions!B33*Assumptions!B34*Assumptions!B32)+(Assumptions!B36*Assumptions!B37*Assumptions!B32) -> 8112 | K9: =(Assumptions!B33*Assumptions!B34*Assumptions!B32)+(Assumptions!B36*Assumptions!B37*Assumptions!B32) -> 8112 | L9: =(Assumptions!B33*Assumptions!B34*Assumptions!B32)+(Assumptions!B36*Assumptions!B37*Assumptions!B32) -> 8112 | M9: =(Assumptions!B33*Assumptions!B34*Assumptions!B32)+(Assumptions!B36*Assumptions!B37*Assumptions!B32) -> 8112 | O9: =(Assumptions!C33*Assumptions!B34*Assumptions!B32)+(Assumptions!C36*Assumptions!B37*Assumptions!B32) -> 16224 | P9: =(Assumptions!C33*Assumptions!B34*Assumptions!B32)+(Assumptions!C36*Assumptions!B37*Assumptions!B32) -> 16224 | Q9: =(Assumptions!C33*Assumptions!B34*Assumptions!B32)+(Assumptions!C36*Assumptions!B37*Assumptions!B32) -> 16224 | R9: =(Assumptions!C33*Assumptions!B34*Assumptions!B32)+(Assumptions!C36*Assumptions!B37*Assumptions!B32) -> 16224 | S9: =(Assumptions!C33*Assumptions!B34*Assumptions!B32)+(Assumptions!C36*Assumptions!B37*Assumptions!B32) -> 16224 | T9: =(Assumptions!C33*Assumptions!B34*Assumptions!B32)+(Assumptions!C36*Assumptions!B37*Assumptions!B32) -> 16224 | U9: =(Assumptions!C33*Assumptions!B34*Assumptions!B32)+(Assumptions!C36*Assumptions!B37*Assumptions!B32) -> 16224 | V9: =(Assumptions!C33*Assumptions!B34*Assumptions!B32)+(Assumptions!C36*Assumptions!B37*Assumptions!B32) -> 16224 | W9: =(Assumptions!C33*Assumptions!B34*Assumptions!B32)+(Assumptions!C36*Assumptions!B37*Assumptions!B32) -> 16224 | X9: =(Assumptions!C33*Assumptions!B34*Assumptions!B32)+(Assumptions!C36*Assumptions!B37*Assumptions!B32) -> 16224 | Y9: =(Assumptions!C33*Assumptions!B34*Assumptions!B32)+(Assumptions!C36*Assumptions!B37*Assumptions!B32) -> 16224 | Z9: =(Assumptions!C33*Assumptions!B34*Assumptions!B32)+(Assumptions!C36*Assumptions!B37*Assumptions!B32) -> 16224 | AB9: =(Assumptions!D33*Assumptions!B34*Assumptions!B32)+(Assumptions!D36*Assumptions!B37*Assumptions!B32) -> 28184 | AC9: =(Assumptions!D33*Assumptions!B34*Assumptions!B32)+(Assumptions!D36*Assumptions!B37*Assumptions!B32) -> 28184 | AD9: =(Assumptions!D33*Assumptions!B34*Assumptions!B32)+(Assumptions!D36*Assumptions!B37*Assumptions!B32) -> 28184 | AE9: =(Assumptions!D33*Assumptions!B34*Assumptions!B32)+(Assumptions!D36*Assumptions!B37*Assumptions!B32) -> 28184 | AF9: =(Assumptions!D33*Assumptions!B34*Assumptions!B32)+(Assumptions!D36*Assumptions!B37*Assumptions!B32) -> 28184 | AG9: =(Assumptions!D33*Assumptions!B34*Assumptions!B32)+(Assumptions!D36*Assumptions!B37*Assumptions!B32) -> 28184 | AH9: =(Assumptions!D33*Assumptions!B34*Assumptions!B32)+(Assumptions!D36*Assumptions!B37*Assumptions!B32) -> 28184 | AI9: =(Assumptions!D33*Assumptions!B34*Assumptions!B32)+(Assumptions!D36*Assumptions!B37*Assumptions!B32) -> 28184 | AJ9: =(Assumptions!D33*Assumptions!B34*Assumptions!B32)+(Assumptions!D36*Assumptions!B37*Assumptions!B32) -> 28184 | AK9: =(Assumptions!D33*Assumptions!B34*Assumptions!B32)+(Assumptions!D36*Assumptions!B37*Assumptions!B32) -> 28184 | AL9: =(Assumptions!D33*Assumptions!B34*Assumptions!B32)+(Assumptions!D36*Assumptions!B37*Assumptions!B32) -> 28184 | AM9: =(Assumptions!D33*Assumptions!B34*Assumptions!B32)+(Assumptions!D36*Assumptions!B37*Assumptions!B32) -> 28184
A10: Actual Deliveries / Month — at Utilisation Target (#) | B10: =MIN(B8,B9*Assumptions!B42) -> 240 | C10: =MIN(C8,C9*Assumptions!B42) -> 285.17538 | D10: =MIN(D8,D9*Assumptions!B42) -> 338.85417 | E10: =MIN(E8,E9*Assumptions!B42) -> 402.63695 | F10: =MIN(F8,F9*Assumptions!B42) -> 478.42561 | G10: =MIN(G8,G9*Assumptions!B42) -> 568.48003 | H10: =MIN(H8,H9*Assumptions!B42) -> 675.48547 | I10: =MIN(I8,I9*Assumptions!B42) -> 802.63262 | J10: =MIN(J8,J9*Assumptions!B42) -> 953.71277 | K10: =MIN(K8,K9*Assumptions!B42) -> 1133.2309 | L10: =MIN(L8,L9*Assumptions!B42) -> 1346.5398 | M10: =MIN(M8,M9*Assumptions!B42) -> 1600 | O10: =MIN(O8,O9*Assumptions!B42) -> 2469.4165 | P10: =MIN(P8,P9*Assumptions!B42) -> 2771.8263 | Q10: =MIN(Q8,Q9*Assumptions!B42) -> 3111.2698 | R10: =MIN(R8,R9*Assumptions!B42) -> 3492.2823 | S10: =MIN(S8,S9*Assumptions!B42) -> 3919.9544 | T10: =MIN(T8,T9*Assumptions!B42) -> 4400 | U10: =MIN(U8,U9*Assumptions!B42) -> 4938.833 | V10: =MIN(V8,V9*Assumptions!B42) -> 5543.6526 | W10: =MIN(W8,W9*Assumptions!B42) -> 6222.5397 | X10: =MIN(X8,X9*Assumptions!B42) -> 6984.5646 | Y10: =MIN(Y8,Y9*Assumptions!B42) -> 7839.9087 | Z10: =MIN(Z8,Z9*Assumptions!B42) -> 8800 | AB10: =MIN(AB8,AB9*Assumptions!B42) -> 11865.987 | AC10: =MIN(AC8,AC9*Assumptions!B42) -> 12571.575 | AD10: =MIN(AD8,AD9*Assumptions!B42) -> 13319.12 | AE10: =MIN(AE8,AE9*Assumptions!B42) -> 14111.116 | AF10: =MIN(AF8,AF9*Assumptions!B42) -> 14950.206 | AG10: =MIN(AG8,AG9*Assumptions!B42) -> 15839.192 | AH10: =MIN(AH8,AH9*Assumptions!B42) -> 16781.039 | AI10: =MIN(AI8,AI9*Assumptions!B42) -> 17778.892 | AJ10: =MIN(AJ8,AJ9*Assumptions!B42) -> 18836.08 | AK10: =MIN(AK8,AK9*Assumptions!B42) -> 19956.131 | AL10: =MIN(AL8,AL9*Assumptions!B42) -> 21138 | AM10: =MIN(AM8,AM9*Assumptions!B42) -> 21138 | AO10: =SUM(B10:M10) -> 8825.1736 | AP10: =SUM(O10:Z10) -> 60494.248 | AQ10: =SUM(AB10:AM10) -> 198285.34
A11: Zone A Deliveries — Doha Metro (#) | B11: =ROUND(B10*Assumptions!B22,0) -> 173 | C11: =ROUND(C10*Assumptions!B22,0) -> 205 | D11: =ROUND(D10*Assumptions!B22,0) -> 244 | E11: =ROUND(E10*Assumptions!B22,0) -> 290 | F11: =ROUND(F10*Assumptions!B22,0) -> 344 | G11: =ROUND(G10*Assumptions!B22,0) -> 409 | H11: =ROUND(H10*Assumptions!B22,0) -> 486 | I11: =ROUND(I10*Assumptions!B22,0) -> 578 | J11: =ROUND(J10*Assumptions!B22,0) -> 687 | K11: =ROUND(K10*Assumptions!B22,0) -> 816 | L11: =ROUND(L10*Assumptions!B22,0) -> 970 | M11: =ROUND(M10*Assumptions!B22,0) -> 1152 | O11: =ROUND(O10*Assumptions!B22,0) -> 1778 | P11: =ROUND(P10*Assumptions!B22,0) -> 1996 | Q11: =ROUND(Q10*Assumptions!B22,0) -> 2240 | R11: =ROUND(R10*Assumptions!B22,0) -> 2514 | S11: =ROUND(S10*Assumptions!B22,0) -> 2822 | T11: =ROUND(T10*Assumptions!B22,0) -> 3168 | U11: =ROUND(U10*Assumptions!B22,0) -> 3556 | V11: =ROUND(V10*Assumptions!B22,0) -> 3991 | W11: =ROUND(W10*Assumptions!B22,0) -> 4480 | X11: =ROUND(X10*Assumptions!B22,0) -> 5029 | Y11: =ROUND(Y10*Assumptions!B22,0) -> 5645 | Z11: =ROUND(Z10*Assumptions!B22,0) -> 6336 | AB11: =ROUND(AB10*Assumptions!B22,0) -> 8544 | AC11: =ROUND(AC10*Assumptions!B22,0) -> 9052 | AD11: =ROUND(AD10*Assumptions!B22,0) -> 9590 | AE11: =ROUND(AE10*Assumptions!B22,0) -> 10160 | AF11: =ROUND(AF10*Assumptions!B22,0) -> 10764 | AG11: =ROUND(AG10*Assumptions!B22,0) -> 11404 | AH11: =ROUND(AH10*Assumptions!B22,0) -> 12082 | AI11: =ROUND(AI10*Assumptions!B22,0) -> 12801 | AJ11: =ROUND(AJ10*Assumptions!B22,0) -> 13562 | AK11: =ROUND(AK10*Assumptions!B22,0) -> 14368 | AL11: =ROUND(AL10*Assumptions!B22,0) -> 15219 | AM11: =ROUND(AM10*Assumptions!B22,0) -> 15219 | AO11: =SUM(B11:M11) -> 6354 | AP11: =SUM(O11:Z11) -> 43555 | AQ11: =SUM(AB11:AM11) -> 142765
A12: Zone B Deliveries — Greater Doha (#) | B12: =B10-B11 -> 67 | C12: =C10-C11 -> 80.175385 | D12: =D10-D11 -> 94.854167 | E12: =E10-E11 -> 112.63695 | F12: =F10-F11 -> 134.42561 | G12: =G10-G11 -> 159.48003 | H12: =H10-H11 -> 189.48547 | I12: =I10-I11 -> 224.63262 | ... M12: =M10-M11 -> 448 | O12: =O10-O11 -> 691.41651 | P12: =P10-P11 -> 775.82631 | Q12: =Q10-Q11 -> 871.26984 | R12: =R10-R11 -> 978.28231 | S12: =S10-S11 -> 1097.9544 | T12: =T10-T11 -> 1232 | U12: =U10-U11 -> 1382.833 | V12: =V10-V11 -> 1552.6526 | ... Z12: =Z10-Z11 -> 2464 | AB12: =AB10-AB11 -> 3321.9867 | AC12: =AC10-AC11 -> 3519.5749 | AD12: =AD10-AD11 -> 3729.1197 | AE12: =AE10-AE11 -> 3951.1158 | AF12: =AF10-AF11 -> 4186.2064 | AG12: =AG10-AG11 -> 4435.1919 | AH12: =AH10-AH11 -> 4699.0393 | AI12: =AI10-AI11 -> 4977.8918 | ... AM12: =AM10-AM11 -> 5919 | AO12: =SUM(B12:M12) -> 2471.1736 | AP12: =SUM(O12:Z12) -> 16939.248 | AQ12: =SUM(AB12:AM12) -> 55520.337
A13: COD Parcels / Month (#) | B13: =ROUND(B10*Assumptions!B25,0) -> 84 | C13: =ROUND(C10*Assumptions!B25,0) -> 100 | D13: =ROUND(D10*Assumptions!B25,0) -> 119 | E13: =ROUND(E10*Assumptions!B25,0) -> 141 | F13: =ROUND(F10*Assumptions!B25,0) -> 167 | G13: =ROUND(G10*Assumptions!B25,0) -> 199 | H13: =ROUND(H10*Assumptions!B25,0) -> 236 | I13: =ROUND(I10*Assumptions!B25,0) -> 281 | J13: =ROUND(J10*Assumptions!B25,0) -> 334 | K13: =ROUND(K10*Assumptions!B25,0) -> 397 | L13: =ROUND(L10*Assumptions!B25,0) -> 471 | M13: =ROUND(M10*Assumptions!B25,0) -> 560 | O13: =ROUND(O10*Assumptions!C25,0) -> 691 | P13: =ROUND(P10*Assumptions!C25,0) -> 776 | Q13: =ROUND(Q10*Assumptions!C25,0) -> 871 | R13: =ROUND(R10*Assumptions!C25,0) -> 978 | S13: =ROUND(S10*Assumptions!C25,0) -> 1098 | T13: =ROUND(T10*Assumptions!C25,0) -> 1232 | U13: =ROUND(U10*Assumptions!C25,0) -> 1383 | V13: =ROUND(V10*Assumptions!C25,0) -> 1552 | W13: =ROUND(W10*Assumptions!C25,0) -> 1742 | X13: =ROUND(X10*Assumptions!C25,0) -> 1956 | Y13: =ROUND(Y10*Assumptions!C25,0) -> 2195 | Z13: =ROUND(Z10*Assumptions!C25,0) -> 2464 | AB13: =ROUND(AB10*Assumptions!D25,0) -> 2611 | AC13: =ROUND(AC10*Assumptions!D25,0) -> 2766 | AD13: =ROUND(AD10*Assumptions!D25,0) -> 2930 | AE13: =ROUND(AE10*Assumptions!D25,0) -> 3104 | AF13: =ROUND(AF10*Assumptions!D25,0) -> 3289 | AG13: =ROUND(AG10*Assumptions!D25,0) -> 3485 | AH13: =ROUND(AH10*Assumptions!D25,0) -> 3692 | AI13: =ROUND(AI10*Assumptions!D25,0) -> 3911 | AJ13: =ROUND(AJ10*Assumptions!D25,0) -> 4144 | AK13: =ROUND(AK10*Assumptions!D25,0) -> 4390 | AL13: =ROUND(AL10*Assumptions!D25,0) -> 4650 | AM13: =ROUND(AM10*Assumptions!D25,0) -> 4650 | AO13: =SUM(B13:M13) -> 3089 | AP13: =SUM(O13:Z13) -> 16938 | AQ13: =SUM(AB13:AM13) -> 43622
A14: Returns / Failed Deliveries / Month (#) | B14: =ROUND(B10*Assumptions!B28,0) -> 14 | C14: =ROUND(C10*Assumptions!B28,0) -> 17 | D14: =ROUND(D10*Assumptions!B28,0) -> 20 | E14: =ROUND(E10*Assumptions!B28,0) -> 24 | F14: =ROUND(F10*Assumptions!B28,0) -> 29 | G14: =ROUND(G10*Assumptions!B28,0) -> 34 | H14: =ROUND(H10*Assumptions!B28,0) -> 41 | I14: =ROUND(I10*Assumptions!B28,0) -> 48 | J14: =ROUND(J10*Assumptions!B28,0) -> 57 | K14: =ROUND(K10*Assumptions!B28,0) -> 68 | L14: =ROUND(L10*Assumptions!B28,0) -> 81 | M14: =ROUND(M10*Assumptions!B28,0) -> 96 | O14: =ROUND(O10*Assumptions!B28,0) -> 148 | P14: =ROUND(P10*Assumptions!B28,0) -> 166 | Q14: =ROUND(Q10*Assumptions!B28,0) -> 187 | R14: =ROUND(R10*Assumptions!B28,0) -> 210 | S14: =ROUND(S10*Assumptions!B28,0) -> 235 | T14: =ROUND(T10*Assumptions!B28,0) -> 264 | U14: =ROUND(U10*Assumptions!B28,0) -> 296 | V14: =ROUND(V10*Assumptions!B28,0) -> 333 | W14: =ROUND(W10*Assumptions!B28,0) -> 373 | X14: =ROUND(X10*Assumptions!B28,0) -> 419 | Y14: =ROUND(Y10*Assumptions!B28,0) -> 470 | Z14: =ROUND(Z10*Assumptions!B28,0) -> 528 | AB14: =ROUND(AB10*Assumptions!B28,0) -> 712 | AC14: =ROUND(AC10*Assumptions!B28,0) -> 754 | AD14: =ROUND(AD10*Assumptions!B28,0) -> 799 | AE14: =ROUND(AE10*Assumptions!B28,0) -> 847 | AF14: =ROUND(AF10*Assumptions!B28,0) -> 897 | AG14: =ROUND(AG10*Assumptions!B28,0) -> 950 | AH14: =ROUND(AH10*Assumptions!B28,0) -> 1007 | AI14: =ROUND(AI10*Assumptions!B28,0) -> 1067 | AJ14: =ROUND(AJ10*Assumptions!B28,0) -> 1130 | AK14: =ROUND(AK10*Assumptions!B28,0) -> 1197 | AL14: =ROUND(AL10*Assumptions!B28,0) -> 1268 | AM14: =ROUND(AM10*Assumptions!B28,0) -> 1268 | AO14: =SUM(B14:M14) -> 529 | AP14: =SUM(O14:Z14) -> 3629 | AQ14: =SUM(AB14:AM14) -> 11896
A15: Total Delivery Trips Required / Month (#) | B15: =IFERROR(ROUND(B10/Assumptions!B43,0),0) -> 273 | C15: =IFERROR(ROUND(C10/Assumptions!B43,0),0) -> 324 | D15: =IFERROR(ROUND(D10/Assumptions!B43,0),0) -> 385 | E15: =IFERROR(ROUND(E10/Assumptions!B43,0),0) -> 458 | F15: =IFERROR(ROUND(F10/Assumptions!B43,0),0) -> 544 | G15: =IFERROR(ROUND(G10/Assumptions!B43,0),0) -> 646 | H15: =IFERROR(ROUND(H10/Assumptions!B43,0),0) -> 768 | I15: =IFERROR(ROUND(I10/Assumptions!B43,0),0) -> 912 | J15: =IFERROR(ROUND(J10/Assumptions!B43,0),0) -> 1084 | K15: =IFERROR(ROUND(K10/Assumptions!B43,0),0) -> 1288 | L15: =IFERROR(ROUND(L10/Assumptions!B43,0),0) -> 1530 | M15: =IFERROR(ROUND(M10/Assumptions!B43,0),0) -> 1818 | O15: =IFERROR(ROUND(O10/Assumptions!B43,0),0) -> 2806 | P15: =IFERROR(ROUND(P10/Assumptions!B43,0),0) -> 3150 | Q15: =IFERROR(ROUND(Q10/Assumptions!B43,0),0) -> 3536 | R15: =IFERROR(ROUND(R10/Assumptions!B43,0),0) -> 3969 | S15: =IFERROR(ROUND(S10/Assumptions!B43,0),0) -> 4454 | T15: =IFERROR(ROUND(T10/Assumptions!B43,0),0) -> 5000 | U15: =IFERROR(ROUND(U10/Assumptions!B43,0),0) -> 5612 | V15: =IFERROR(ROUND(V10/Assumptions!B43,0),0) -> 6300 | W15: =IFERROR(ROUND(W10/Assumptions!B43,0),0) -> 7071 | X15: =IFERROR(ROUND(X10/Assumptions!B43,0),0) -> 7937 | Y15: =IFERROR(ROUND(Y10/Assumptions!B43,0),0) -> 8909 | Z15: =IFERROR(ROUND(Z10/Assumptions!B43,0),0) -> 10000 | AB15: =IFERROR(ROUND(AB10/Assumptions!B43,0),0) -> 13484 | AC15: =IFERROR(ROUND(AC10/Assumptions!B43,0),0) -> 14286 | AD15: =IFERROR(ROUND(AD10/Assumptions!B43,0),0) -> 15135 | AE15: =IFERROR(ROUND(AE10/Assumptions!B43,0),0) -> 16035 | AF15: =IFERROR(ROUND(AF10/Assumptions!B43,0),0) -> 16989 | AG15: =IFERROR(ROUND(AG10/Assumptions!B43,0),0) -> 17999 | AH15: =IFERROR(ROUND(AH10/Assumptions!B43,0),0) -> 19069 | AI15: =IFERROR(ROUND(AI10/Assumptions!B43,0),0) -> 20203 | AJ15: =IFERROR(ROUND(AJ10/Assumptions!B43,0),0) -> 21405 | AK15: =IFERROR(ROUND(AK10/Assumptions!B43,0),0) -> 22677 | AL15: =IFERROR(ROUND(AL10/Assumptions!B43,0),0) -> 24020 | AM15: =IFERROR(ROUND(AM10/Assumptions!B43,0),0) -> 24020 | AO15: =SUM(B15:M15) -> 10030 | AP15: =SUM(O15:Z15) -> 68744 | AQ15: =SUM(AB15:AM15) -> 225322
A16: Market Penetration — Deliveries as % of SAM/Month | B16: =IFERROR(B10/Assumptions!B11,0) -> 0.00026315789 | C16: =IFERROR(C10/Assumptions!B11,0) -> 0.00031269231 | D16: =IFERROR(D10/Assumptions!B11,0) -> 0.00037155062 | E16: =IFERROR(E10/Assumptions!B11,0) -> 0.00044148788 | F16: =IFERROR(F10/Assumptions!B11,0) -> 0.00052458949 | G16: =IFERROR(G10/Assumptions!B11,0) -> 0.00062333337 | H16: =IFERROR(H10/Assumptions!B11,0) -> 0.00074066389 | I16: =IFERROR(I10/Assumptions!B11,0) -> 0.00088007962 | J16: =IFERROR(J10/Assumptions!B11,0) -> 0.0010457377 | K16: =IFERROR(K10/Assumptions!B11,0) -> 0.0012425777 | L16: =IFERROR(L10/Assumptions!B11,0) -> 0.0014764691 | M16: =IFERROR(M10/Assumptions!B11,0) -> 0.001754386 | O16: =IFERROR(O10/Assumptions!B11,0) -> 0.0027076935 | P16: =IFERROR(P10/Assumptions!B11,0) -> 0.0030392832 | Q16: =IFERROR(Q10/Assumptions!B11,0) -> 0.0034114801 | R16: =IFERROR(R10/Assumptions!B11,0) -> 0.0038292569 | S16: =IFERROR(S10/Assumptions!B11,0) -> 0.0042981956 | T16: =IFERROR(T10/Assumptions!B11,0) -> 0.0048245614 | U16: =IFERROR(U10/Assumptions!B11,0) -> 0.0054153871 | V16: =IFERROR(V10/Assumptions!B11,0) -> 0.0060785665 | W16: =IFERROR(W10/Assumptions!B11,0) -> 0.0068229602 | X16: =IFERROR(X10/Assumptions!B11,0) -> 0.0076585138 | Y16: =IFERROR(Y10/Assumptions!B11,0) -> 0.0085963911 | Z16: =IFERROR(Z10/Assumptions!B11,0) -> 0.0096491228 | AB16: =IFERROR(AB10/Assumptions!B11,0) -> 0.01301095 | AC16: =IFERROR(AC10/Assumptions!B11,0) -> 0.013784622 | AD16: =IFERROR(AD10/Assumptions!B11,0) -> 0.014604298 | AE16: =IFERROR(AE10/Assumptions!B11,0) -> 0.015472715 | AF16: =IFERROR(AF10/Assumptions!B11,0) -> 0.01639277 | AG16: =IFERROR(AG10/Assumptions!B11,0) -> 0.017367535 | AH16: =IFERROR(AH10/Assumptions!B11,0) -> 0.018400262 | AI16: =IFERROR(AI10/Assumptions!B11,0) -> 0.019494399 | AJ16: =IFERROR(AJ10/Assumptions!B11,0) -> 0.020653596 | AK16: =IFERROR(AK10/Assumptions!B11,0) -> 0.021881723 | AL16: =IFERROR(AL10/Assumptions!B11,0) -> 0.023177632 | AM16: =IFERROR(AM10/Assumptions!B11,0) -> 0.023177632
A18: DRIVER CAPACITY SPLIT
A19: Contracted Driver Deliveries / Month (#) | B19: =IFERROR(ROUND(Assumptions!B33*Assumptions!B34*Assumptions!B32/B9*B15,0),0) -> 158 | C19: =IFERROR(ROUND(Assumptions!B33*Assumptions!B34*Assumptions!B32/C9*C15,0),0) -> 187 | D19: =IFERROR(ROUND(Assumptions!B33*Assumptions!B34*Assumptions!B32/D9*D15,0),0) -> 222 | E19: =IFERROR(ROUND(Assumptions!B33*Assumptions!B34*Assumptions!B32/E9*E15,0),0) -> 264 | F19: =IFERROR(ROUND(Assumptions!B33*Assumptions!B34*Assumptions!B32/F9*F15,0),0) -> 314 | G19: =IFERROR(ROUND(Assumptions!B33*Assumptions!B34*Assumptions!B32/G9*G15,0),0) -> 373 | H19: =IFERROR(ROUND(Assumptions!B33*Assumptions!B34*Assumptions!B32/H9*H15,0),0) -> 443 | I19: =IFERROR(ROUND(Assumptions!B33*Assumptions!B34*Assumptions!B32/I9*I15,0),0) -> 526 | J19: =IFERROR(ROUND(Assumptions!B33*Assumptions!B34*Assumptions!B32/J9*J15,0),0) -> 625 | K19: =IFERROR(ROUND(Assumptions!B33*Assumptions!B34*Assumptions!B32/K9*K15,0),0) -> 743 | L19: =IFERROR(ROUND(Assumptions!B33*Assumptions!B34*Assumptions!B32/L9*L15,0),0) -> 883 | M19: =IFERROR(ROUND(Assumptions!B33*Assumptions!B34*Assumptions!B32/M9*M15,0),0) -> 1049 | O19: =IFERROR(ROUND(Assumptions!C33*Assumptions!B34*Assumptions!B32/O9*O15,0),0) -> 1619 | P19: =IFERROR(ROUND(Assumptions!C33*Assumptions!B34*Assumptions!B32/P9*P15,0),0) -> 1817 | Q19: =IFERROR(ROUND(Assumptions!C33*Assumptions!B34*Assumptions!B32/Q9*Q15,0),0) -> 2040 | R19: =IFERROR(ROUND(Assumptions!C33*Assumptions!B34*Assumptions!B32/R9*R15,0),0) -> 2290 | S19: =IFERROR(ROUND(Assumptions!C33*Assumptions!B34*Assumptions!B32/S9*S15,0),0) -> 2570 | T19: =IFERROR(ROUND(Assumptions!C33*Assumptions!B34*Assumptions!B32/T9*T15,0),0) -> 2885 | U19: =IFERROR(ROUND(Assumptions!C33*Assumptions!B34*Assumptions!B32/U9*U15,0),0) -> 3238 | V19: =IFERROR(ROUND(Assumptions!C33*Assumptions!B34*Assumptions!B32/V9*V15,0),0) -> 3635 | W19: =IFERROR(ROUND(Assumptions!C33*Assumptions!B34*Assumptions!B32/W9*W15,0),0) -> 4079 | X19: =IFERROR(ROUND(Assumptions!C33*Assumptions!B34*Assumptions!B32/X9*X15,0),0) -> 4579 | Y19: =IFERROR(ROUND(Assumptions!C33*Assumptions!B34*Assumptions!B32/Y9*Y15,0),0) -> 5140 | Z19: =IFERROR(ROUND(Assumptions!C33*Assumptions!B34*Assumptions!B32/Z9*Z15,0),0) -> 5769 | AB19: =IFERROR(ROUND(Assumptions!D33*Assumptions!B34*Assumptions!B32/AB9*AB15,0),0) -> 7463 | AC19: =IFERROR(ROUND(Assumptions!D33*Assumptions!B34*Assumptions!B32/AC9*AC15,0),0) -> 7907 | AD19: =IFERROR(ROUND(Assumptions!D33*Assumptions!B34*Assumptions!B32/AD9*AD15,0),0) -> 8377 | AE19: =IFERROR(ROUND(Assumptions!D33*Assumptions!B34*Assumptions!B32/AE9*AE15,0),0) -> 8875 | AF19: =IFERROR(ROUND(Assumptions!D33*Assumptions!B34*Assumptions!B32/AF9*AF15,0),0) -> 9404 | AG19: =IFERROR(ROUND(Assumptions!D33*Assumptions!B34*Assumptions!B32/AG9*AG15,0),0) -> 9963 | AH19: =IFERROR(ROUND(Assumptions!D33*Assumptions!B34*Assumptions!B32/AH9*AH15,0),0) -> 10555 | AI19: =IFERROR(ROUND(Assumptions!D33*Assumptions!B34*Assumptions!B32/AI9*AI15,0),0) -> 11182 | AJ19: =IFERROR(ROUND(Assumptions!D33*Assumptions!B34*Assumptions!B32/AJ9*AJ15,0),0) -> 11848 | AK19: =IFERROR(ROUND(Assumptions!D33*Assumptions!B34*Assumptions!B32/AK9*AK15,0),0) -> 12552 | AL19: =IFERROR(ROUND(Assumptions!D33*Assumptions!B34*Assumptions!B32/AL9*AL15,0),0) -> 13295 | AM19: =IFERROR(ROUND(Assumptions!D33*Assumptions!B34*Assumptions!B32/AM9*AM15,0),0) -> 13295 | AO19: =SUM(B19:M19) -> 5787 | AP19: =SUM(O19:Z19) -> 39661 | AQ19: =SUM(AB19:AM19) -> 124716
A20: Employed Driver Deliveries / Month (#) | B20: =B15-B19 -> 115 | C20: =C15-C19 -> 137 | D20: =D15-D19 -> 163 | E20: =E15-E19 -> 194 | F20: =F15-F19 -> 230 | G20: =G15-G19 -> 273 | H20: =H15-H19 -> 325 | I20: =I15-I19 -> 386 | ... M20: =M15-M19 -> 769 | O20: =O15-O19 -> 1187 | P20: =P15-P19 -> 1333 | Q20: =Q15-Q19 -> 1496 | R20: =R15-R19 -> 1679 | S20: =S15-S19 -> 1884 | T20: =T15-T19 -> 2115 | U20: =U15-U19 -> 2374 | V20: =V15-V19 -> 2665 | ... Z20: =Z15-Z19 -> 4231 | AB20: =AB15-AB19 -> 6021 | AC20: =AC15-AC19 -> 6379 | AD20: =AD15-AD19 -> 6758 | AE20: =AE15-AE19 -> 7160 | AF20: =AF15-AF19 -> 7585 | AG20: =AG15-AG19 -> 8036 | AH20: =AH15-AH19 -> 8514 | AI20: =AI15-AI19 -> 9021 | ... AM20: =AM15-AM19 -> 10725 | AO20: =SUM(B20:M20) -> 4243 | AP20: =SUM(O20:Z20) -> 29083 | AQ20: =SUM(AB20:AM20) -> 100606
B21: Note: FY columns show SUM for delivery flows. Merchant accounts FY = December end-of-year value.

Sheet Monthly P&L
A1: LAST-MILE DELIVERY SERVICE | MONTHLY P&L
A2: All figures QAR. Costs shown as negatives. Driven by Volume & Funnel and Assumptions tabs.
B3: YEAR 1 (2026) | O3: YEAR 2 (2027) | AB3: YEAR 3 (2028) | AO3: FY1 Total | AP3: FY2 Total | AQ3: FY3 Total
B4: Y1M1 | C4: Y1M2 | D4: Y1M3 | E4: Y1M4 | F4: Y1M5 | G4: Y1M6 | H4: Y1M7 | I4: Y1M8 | J4: Y1M9 | K4: Y1M10 | L4: Y1M11 | M4: Y1M12 | O4: Y2M1 | P4: Y2M2 | Q4: Y2M3 | R4: Y2M4 | S4: Y2M5 | T4: Y2M6 | U4: Y2M7 | V4: Y2M8 | W4: Y2M9 | X4: Y2M10 | Y4: Y2M11 | Z4: Y2M12 | AB4: Y3M1 | AC4: Y3M2 | AD4: Y3M3 | AE4: Y3M4 | AF4: Y3M5 | AG4: Y3M6 | AH4: Y3M7 | AI4: Y3M8 | AJ4: Y3M9 | AK4: Y3M10 | AL4: Y3M11 | AM4: Y3M12
A5: REVENUE
A6: Zone A Delivery Fee Revenue (QAR) | B6: ='Volume & Funnel'!B11*Assumptions!B20 -> 3114 | C6: ='Volume & Funnel'!C11*Assumptions!B20 -> 3690 | D6: ='Volume & Funnel'!D11*Assumptions!B20 -> 4392 | E6: ='Volume & Funnel'!E11*Assumptions!B20 -> 5220 | F6: ='Volume & Funnel'!F11*Assumptions!B20 -> 6192 | G6: ='Volume & Funnel'!G11*Assumptions!B20 -> 7362 | H6: ='Volume & Funnel'!H11*Assumptions!B20 -> 8748 | I6: ='Volume & Funnel'!I11*Assumptions!B20 -> 10404 | J6: ='Volume & Funnel'!J11*Assumptions!B20 -> 12366 | K6: ='Volume & Funnel'!K11*Assumptions!B20 -> 14688 | L6: ='Volume & Funnel'!L11*Assumptions!B20 -> 17460 | M6: ='Volume & Funnel'!M11*Assumptions!B20 -> 20736 | O6: ='Volume & Funnel'!O11*Assumptions!B20 -> 32004 | P6: ='Volume & Funnel'!P11*Assumptions!B20 -> 35928 | Q6: ='Volume & Funnel'!Q11*Assumptions!B20 -> 40320 | R6: ='Volume & Funnel'!R11*Assumptions!B20 -> 45252 | S6: ='Volume & Funnel'!S11*Assumptions!B20 -> 50796 | T6: ='Volume & Funnel'!T11*Assumptions!B20 -> 57024 | U6: ='Volume & Funnel'!U11*Assumptions!B20 -> 64008 | V6: ='Volume & Funnel'!V11*Assumptions!B20 -> 71838 | W6: ='Volume & Funnel'!W11*Assumptions!B20 -> 80640 | X6: ='Volume & Funnel'!X11*Assumptions!B20 -> 90522 | Y6: ='Volume & Funnel'!Y11*Assumptions!B20 -> 101610 | Z6: ='Volume & Funnel'!Z11*Assumptions!B20 -> 114048 | AB6: ='Volume & Funnel'!AB11*Assumptions!B20 -> 153792 | AC6: ='Volume & Funnel'!AC11*Assumptions!B20 -> 162936 | AD6: ='Volume & Funnel'!AD11*Assumptions!B20 -> 172620 | AE6: ='Volume & Funnel'!AE11*Assumptions!B20 -> 182880 | AF6: ='Volume & Funnel'!AF11*Assumptions!B20 -> 193752 | AG6: ='Volume & Funnel'!AG11*Assumptions!B20 -> 205272 | AH6: ='Volume & Funnel'!AH11*Assumptions!B20 -> 217476 | AI6: ='Volume & Funnel'!AI11*Assumptions!B20 -> 230418 | AJ6: ='Volume & Funnel'!AJ11*Assumptions!B20 -> 244116 | AK6: ='Volume & Funnel'!AK11*Assumptions!B20 -> 258624 | AL6: ='Volume & Funnel'!AL11*Assumptions!B20 -> 273942 | AM6: ='Volume & Funnel'!AM11*Assumptions!B20 -> 273942 | AO6: =SUM(B6:M6) -> 114372 | AP6: =SUM(O6:Z6) -> 783990 | AQ6: =SUM(AB6:AM6) -> 2569770
A7: Zone B Delivery Fee Revenue (QAR) | B7: ='Volume & Funnel'!B12*Assumptions!B21 -> 1474 | C7: ='Volume & Funnel'!C12*Assumptions!B21 -> 1763.8585 | D7: ='Volume & Funnel'!D12*Assumptions!B21 -> 2086.7917 | E7: ='Volume & Funnel'!E12*Assumptions!B21 -> 2478.0129 | F7: ='Volume & Funnel'!F12*Assumptions!B21 -> 2957.3634 | G7: ='Volume & Funnel'!G12*Assumptions!B21 -> 3508.5607 | H7: ='Volume & Funnel'!H12*Assumptions!B21 -> 4168.6803 | I7: ='Volume & Funnel'!I12*Assumptions!B21 -> 4941.9176 | J7: ='Volume & Funnel'!J12*Assumptions!B21 -> 5867.681 | K7: ='Volume & Funnel'!K12*Assumptions!B21 -> 6979.079 | L7: ='Volume & Funnel'!L12*Assumptions!B21 -> 8283.8752 | M7: ='Volume & Funnel'!M12*Assumptions!B21 -> 9856 | O7: ='Volume & Funnel'!O12*Assumptions!B21 -> 15211.163 | P7: ='Volume & Funnel'!P12*Assumptions!B21 -> 17068.179 | Q7: ='Volume & Funnel'!Q12*Assumptions!B21 -> 19167.936 | R7: ='Volume & Funnel'!R12*Assumptions!B21 -> 21522.211 | S7: ='Volume & Funnel'!S12*Assumptions!B21 -> 24154.996 | T7: ='Volume & Funnel'!T12*Assumptions!B21 -> 27104 | U7: ='Volume & Funnel'!U12*Assumptions!B21 -> 30422.326 | V7: ='Volume & Funnel'!V12*Assumptions!B21 -> 34158.358 | W7: ='Volume & Funnel'!W12*Assumptions!B21 -> 38335.873 | X7: ='Volume & Funnel'!X12*Assumptions!B21 -> 43022.422 | Y7: ='Volume & Funnel'!Y12*Assumptions!B21 -> 48287.992 | Z7: ='Volume & Funnel'!Z12*Assumptions!B21 -> 54208 | AB7: ='Volume & Funnel'!AB12*Assumptions!B21 -> 73083.706 | AC7: ='Volume & Funnel'!AC12*Assumptions!B21 -> 77430.649 | AD7: ='Volume & Funnel'!AD12*Assumptions!B21 -> 82040.633 | AE7: ='Volume & Funnel'!AE12*Assumptions!B21 -> 86924.547 | AF7: ='Volume & Funnel'!AF12*Assumptions!B21 -> 92096.54 | AG7: ='Volume & Funnel'!AG12*Assumptions!B21 -> 97574.222 | AH7: ='Volume & Funnel'!AH12*Assumptions!B21 -> 103378.86 | AI7: ='Volume & Funnel'!AI12*Assumptions!B21 -> 109513.62 | AJ7: ='Volume & Funnel'!AJ12*Assumptions!B21 -> 116029.75 | AK7: ='Volume & Funnel'!AK12*Assumptions!B21 -> 122938.89 | AL7: ='Volume & Funnel'!AL12*Assumptions!B21 -> 130218 | AM7: ='Volume & Funnel'!AM12*Assumptions!B21 -> 130218 | AO7: =SUM(B7:M7) -> 54365.82 | AP7: =SUM(O7:Z7) -> 372663.46 | AQ7: =SUM(AB7:AM7) -> 1221447.4
A8: COD Handling Fee Revenue (QAR) | B8: ='Volume & Funnel'!B13*Assumptions!B26*Assumptions!B24 -> 226.8 | C8: ='Volume & Funnel'!C13*Assumptions!B26*Assumptions!B24 -> 270 | D8: ='Volume & Funnel'!D13*Assumptions!B26*Assumptions!B24 -> 321.3 | E8: ='Volume & Funnel'!E13*Assumptions!B26*Assumptions!B24 -> 380.7 | F8: ='Volume & Funnel'!F13*Assumptions!B26*Assumptions!B24 -> 450.9 | G8: ='Volume & Funnel'!G13*Assumptions!B26*Assumptions!B24 -> 537.3 | H8: ='Volume & Funnel'!H13*Assumptions!B26*Assumptions!B24 -> 637.2 | I8: ='Volume & Funnel'!I13*Assumptions!B26*Assumptions!B24 -> 758.7 | J8: ='Volume & Funnel'!J13*Assumptions!B26*Assumptions!B24 -> 901.8 | K8: ='Volume & Funnel'!K13*Assumptions!B26*Assumptions!B24 -> 1071.9 | L8: ='Volume & Funnel'!L13*Assumptions!B26*Assumptions!B24 -> 1271.7 | M8: ='Volume & Funnel'!M13*Assumptions!B26*Assumptions!B24 -> 1512 | O8: ='Volume & Funnel'!O13*Assumptions!B26*Assumptions!B24 -> 1865.7 | P8: ='Volume & Funnel'!P13*Assumptions!B26*Assumptions!B24 -> 2095.2 | Q8: ='Volume & Funnel'!Q13*Assumptions!B26*Assumptions!B24 -> 2351.7 | R8: ='Volume & Funnel'!R13*Assumptions!B26*Assumptions!B24 -> 2640.6 | S8: ='Volume & Funnel'!S13*Assumptions!B26*Assumptions!B24 -> 2964.6 | T8: ='Volume & Funnel'!T13*Assumptions!B26*Assumptions!B24 -> 3326.4 | U8: ='Volume & Funnel'!U13*Assumptions!B26*Assumptions!B24 -> 3734.1 | V8: ='Volume & Funnel'!V13*Assumptions!B26*Assumptions!B24 -> 4190.4 | W8: ='Volume & Funnel'!W13*Assumptions!B26*Assumptions!B24 -> 4703.4 | X8: ='Volume & Funnel'!X13*Assumptions!B26*Assumptions!B24 -> 5281.2 | Y8: ='Volume & Funnel'!Y13*Assumptions!B26*Assumptions!B24 -> 5926.5 | Z8: ='Volume & Funnel'!Z13*Assumptions!B26*Assumptions!B24 -> 6652.8 | AB8: ='Volume & Funnel'!AB13*Assumptions!B26*Assumptions!B24 -> 7049.7 | AC8: ='Volume & Funnel'!AC13*Assumptions!B26*Assumptions!B24 -> 7468.2 | AD8: ='Volume & Funnel'!AD13*Assumptions!B26*Assumptions!B24 -> 7911 | AE8: ='Volume & Funnel'!AE13*Assumptions!B26*Assumptions!B24 -> 8380.8 | AF8: ='Volume & Funnel'!AF13*Assumptions!B26*Assumptions!B24 -> 8880.3 | AG8: ='Volume & Funnel'!AG13*Assumptions!B26*Assumptions!B24 -> 9409.5 | AH8: ='Volume & Funnel'!AH13*Assumptions!B26*Assumptions!B24 -> 9968.4 | AI8: ='Volume & Funnel'!AI13*Assumptions!B26*Assumptions!B24 -> 10559.7 | AJ8: ='Volume & Funnel'!AJ13*Assumptions!B26*Assumptions!B24 -> 11188.8 | AK8: ='Volume & Funnel'!AK13*Assumptions!B26*Assumptions!B24 -> 11853 | AL8: ='Volume & Funnel'!AL13*Assumptions!B26*Assumptions!B24 -> 12555 | AM8: ='Volume & Funnel'!AM13*Assumptions!B26*Assumptions!B24 -> 12555 | AO8: =SUM(B8:M8) -> 8340.3 | AP8: =SUM(O8:Z8) -> 45732.6 | AQ8: =SUM(AB8:AM8) -> 117779.4
A9: Returns / Failed Delivery Fee Revenue (QAR) | B9: ='Volume & Funnel'!B14*Assumptions!B27 -> 112 | C9: ='Volume & Funnel'!C14*Assumptions!B27 -> 136 | D9: ='Volume & Funnel'!D14*Assumptions!B27 -> 160 | E9: ='Volume & Funnel'!E14*Assumptions!B27 -> 192 | F9: ='Volume & Funnel'!F14*Assumptions!B27 -> 232 | G9: ='Volume & Funnel'!G14*Assumptions!B27 -> 272 | H9: ='Volume & Funnel'!H14*Assumptions!B27 -> 328 | I9: ='Volume & Funnel'!I14*Assumptions!B27 -> 384 | J9: ='Volume & Funnel'!J14*Assumptions!B27 -> 456 | K9: ='Volume & Funnel'!K14*Assumptions!B27 -> 544 | L9: ='Volume & Funnel'!L14*Assumptions!B27 -> 648 | M9: ='Volume & Funnel'!M14*Assumptions!B27 -> 768 | O9: ='Volume & Funnel'!O14*Assumptions!B27 -> 1184 | P9: ='Volume & Funnel'!P14*Assumptions!B27 -> 1328 | Q9: ='Volume & Funnel'!Q14*Assumptions!B27 -> 1496 | R9: ='Volume & Funnel'!R14*Assumptions!B27 -> 1680 | S9: ='Volume & Funnel'!S14*Assumptions!B27 -> 1880 | T9: ='Volume & Funnel'!T14*Assumptions!B27 -> 2112 | U9: ='Volume & Funnel'!U14*Assumptions!B27 -> 2368 | V9: ='Volume & Funnel'!V14*Assumptions!B27 -> 2664 | W9: ='Volume & Funnel'!W14*Assumptions!B27 -> 2984 | X9: ='Volume & Funnel'!X14*Assumptions!B27 -> 3352 | Y9: ='Volume & Funnel'!Y14*Assumptions!B27 -> 3760 | Z9: ='Volume & Funnel'!Z14*Assumptions!B27 -> 4224 | AB9: ='Volume & Funnel'!AB14*Assumptions!B27 -> 5696 | AC9: ='Volume & Funnel'!AC14*Assumptions!B27 -> 6032 | AD9: ='Volume & Funnel'!AD14*Assumptions!B27 -> 6392 | AE9: ='Volume & Funnel'!AE14*Assumptions!B27 -> 6776 | AF9: ='Volume & Funnel'!AF14*Assumptions!B27 -> 7176 | AG9: ='Volume & Funnel'!AG14*Assumptions!B27 -> 7600 | AH9: ='Volume & Funnel'!AH14*Assumptions!B27 -> 8056 | AI9: ='Volume & Funnel'!AI14*Assumptions!B27 -> 8536 | AJ9: ='Volume & Funnel'!AJ14*Assumptions!B27 -> 9040 | AK9: ='Volume & Funnel'!AK14*Assumptions!B27 -> 9576 | AL9: ='Volume & Funnel'!AL14*Assumptions!B27 -> 10144 | AM9: ='Volume & Funnel'!AM14*Assumptions!B27 -> 10144 | AO9: =SUM(B9:M9) -> 4232 | AP9: =SUM(O9:Z9) -> 29032 | AQ9: =SUM(AB9:AM9) -> 95168
A10: TOTAL REVENUE | B10: =SUM(B6:B9) -> 4926.8 | C10: =SUM(C6:C9) -> 5859.8585 | D10: =SUM(D6:D9) -> 6960.0917 | E10: =SUM(E6:E9) -> 8270.7129 | F10: =SUM(F6:F9) -> 9832.2634 | G10: =SUM(G6:G9) -> 11679.861 | H10: =SUM(H6:H9) -> 13881.88 | I10: =SUM(I6:I9) -> 16488.618 | ... M10: =SUM(M6:M9) -> 32872 | O10: =SUM(O6:O9) -> 50264.863 | P10: =SUM(P6:P9) -> 56419.379 | Q10: =SUM(Q6:Q9) -> 63335.636 | R10: =SUM(R6:R9) -> 71094.811 | S10: =SUM(S6:S9) -> 79795.596 | T10: =SUM(T6:T9) -> 89566.4 | U10: =SUM(U6:U9) -> 100532.43 | V10: =SUM(V6:V9) -> 112850.76 | ... Z10: =SUM(Z6:Z9) -> 179132.8 | AB10: =SUM(AB6:AB9) -> 239621.41 | AC10: =SUM(AC6:AC9) -> 253866.85 | AD10: =SUM(AD6:AD9) -> 268963.63 | AE10: =SUM(AE6:AE9) -> 284961.35 | AF10: =SUM(AF6:AF9) -> 301904.84 | AG10: =SUM(AG6:AG9) -> 319855.72 | AH10: =SUM(AH6:AH9) -> 338879.26 | AI10: =SUM(AI6:AI9) -> 359027.32 | ... AM10: =SUM(AM6:AM9) -> 426859 | AO10: =SUM(B10:M10) -> 181310.12 | AP10: =SUM(O10:Z10) -> 1231418.1 | AQ10: =SUM(AB10:AM10) -> 4004164.8
A12: COST OF DELIVERY
A13: Contracted Driver Cost — per drop (QAR) | B13: =-'Volume & Funnel'!B19*Assumptions!B35 -> -1422 | C13: =-'Volume & Funnel'!C19*Assumptions!B35 -> -1683 | D13: =-'Volume & Funnel'!D19*Assumptions!B35 -> -1998 | E13: =-'Volume & Funnel'!E19*Assumptions!B35 -> -2376 | F13: =-'Volume & Funnel'!F19*Assumptions!B35 -> -2826 | G13: =-'Volume & Funnel'!G19*Assumptions!B35 -> -3357 | H13: =-'Volume & Funnel'!H19*Assumptions!B35 -> -3987 | I13: =-'Volume & Funnel'!I19*Assumptions!B35 -> -4734 | J13: =-'Volume & Funnel'!J19*Assumptions!B35 -> -5625 | K13: =-'Volume & Funnel'!K19*Assumptions!B35 -> -6687 | L13: =-'Volume & Funnel'!L19*Assumptions!B35 -> -7947 | M13: =-'Volume & Funnel'!M19*Assumptions!B35 -> -9441 | O13: =-'Volume & Funnel'!O19*Assumptions!B35 -> -14571 | P13: =-'Volume & Funnel'!P19*Assumptions!B35 -> -16353 | Q13: =-'Volume & Funnel'!Q19*Assumptions!B35 -> -18360 | R13: =-'Volume & Funnel'!R19*Assumptions!B35 -> -20610 | S13: =-'Volume & Funnel'!S19*Assumptions!B35 -> -23130 | T13: =-'Volume & Funnel'!T19*Assumptions!B35 -> -25965 | U13: =-'Volume & Funnel'!U19*Assumptions!B35 -> -29142 | V13: =-'Volume & Funnel'!V19*Assumptions!B35 -> -32715 | W13: =-'Volume & Funnel'!W19*Assumptions!B35 -> -36711 | X13: =-'Volume & Funnel'!X19*Assumptions!B35 -> -41211 | Y13: =-'Volume & Funnel'!Y19*Assumptions!B35 -> -46260 | Z13: =-'Volume & Funnel'!Z19*Assumptions!B35 -> -51921 | AB13: =-'Volume & Funnel'!AB19*Assumptions!B35 -> -67167 | AC13: =-'Volume & Funnel'!AC19*Assumptions!B35 -> -71163 | AD13: =-'Volume & Funnel'!AD19*Assumptions!B35 -> -75393 | AE13: =-'Volume & Funnel'!AE19*Assumptions!B35 -> -79875 | AF13: =-'Volume & Funnel'!AF19*Assumptions!B35 -> -84636 | AG13: =-'Volume & Funnel'!AG19*Assumptions!B35 -> -89667 | AH13: =-'Volume & Funnel'!AH19*Assumptions!B35 -> -94995 | AI13: =-'Volume & Funnel'!AI19*Assumptions!B35 -> -100638 | AJ13: =-'Volume & Funnel'!AJ19*Assumptions!B35 -> -106632 | AK13: =-'Volume & Funnel'!AK19*Assumptions!B35 -> -112968 | AL13: =-'Volume & Funnel'!AL19*Assumptions!B35 -> -119655 | AM13: =-'Volume & Funnel'!AM19*Assumptions!B35 -> -119655 | AO13: =SUM(B13:M13) -> -52083 | AP13: =SUM(O13:Z13) -> -356949 | AQ13: =SUM(AB13:AM13) -> -1122444
A14: Employed Driver Cost — monthly salary (QAR) | B14: =-(Assumptions!B36*Assumptions!B38) -> -16800 | C14: =-(Assumptions!B36*Assumptions!B38) -> -16800 | D14: =-(Assumptions!B36*Assumptions!B38) -> -16800 | E14: =-(Assumptions!B36*Assumptions!B38) -> -16800 | F14: =-(Assumptions!B36*Assumptions!B38) -> -16800 | G14: =-(Assumptions!B36*Assumptions!B38) -> -16800 | H14: =-(Assumptions!B36*Assumptions!B38) -> -16800 | I14: =-(Assumptions!B36*Assumptions!B38) -> -16800 | J14: =-(Assumptions!B36*Assumptions!B38) -> -16800 | K14: =-(Assumptions!B36*Assumptions!B38) -> -16800 | L14: =-(Assumptions!B36*Assumptions!B38) -> -16800 | M14: =-(Assumptions!B36*Assumptions!B38) -> -16800 | O14: =-(Assumptions!C36*Assumptions!B38) -> -33600 | P14: =-(Assumptions!C36*Assumptions!B38) -> -33600 | Q14: =-(Assumptions!C36*Assumptions!B38) -> -33600 | R14: =-(Assumptions!C36*Assumptions!B38) -> -33600 | S14: =-(Assumptions!C36*Assumptions!B38) -> -33600 | T14: =-(Assumptions!C36*Assumptions!B38) -> -33600 | U14: =-(Assumptions!C36*Assumptions!B38) -> -33600 | V14: =-(Assumptions!C36*Assumptions!B38) -> -33600 | W14: =-(Assumptions!C36*Assumptions!B38) -> -33600 | X14: =-(Assumptions!C36*Assumptions!B38) -> -33600 | Y14: =-(Assumptions!C36*Assumptions!B38) -> -33600 | Z14: =-(Assumptions!C36*Assumptions!B38) -> -33600 | AB14: =-(Assumptions!D36*Assumptions!B38) -> -61600 | AC14: =-(Assumptions!D36*Assumptions!B38) -> -61600 | AD14: =-(Assumptions!D36*Assumptions!B38) -> -61600 | AE14: =-(Assumptions!D36*Assumptions!B38) -> -61600 | AF14: =-(Assumptions!D36*Assumptions!B38) -> -61600 | AG14: =-(Assumptions!D36*Assumptions!B38) -> -61600 | AH14: =-(Assumptions!D36*Assumptions!B38) -> -61600 | AI14: =-(Assumptions!D36*Assumptions!B38) -> -61600 | AJ14: =-(Assumptions!D36*Assumptions!B38) -> -61600 | AK14: =-(Assumptions!D36*Assumptions!B38) -> -61600 | AL14: =-(Assumptions!D36*Assumptions!B38) -> -61600 | AM14: =-(Assumptions!D36*Assumptions!B38) -> -61600 | AO14: =SUM(B14:M14) -> -201600 | AP14: =SUM(O14:Z14) -> -403200 | AQ14: =SUM(AB14:AM14) -> -739200
A15: Fuel & Vehicle Running Cost (QAR) | B15: =-'Volume & Funnel'!B15*Assumptions!B46 -> -491.4 | C15: =-'Volume & Funnel'!C15*Assumptions!B46 -> -583.2 | D15: =-'Volume & Funnel'!D15*Assumptions!B46 -> -693 | E15: =-'Volume & Funnel'!E15*Assumptions!B46 -> -824.4 | F15: =-'Volume & Funnel'!F15*Assumptions!B46 -> -979.2 | G15: =-'Volume & Funnel'!G15*Assumptions!B46 -> -1162.8 | H15: =-'Volume & Funnel'!H15*Assumptions!B46 -> -1382.4 | I15: =-'Volume & Funnel'!I15*Assumptions!B46 -> -1641.6 | J15: =-'Volume & Funnel'!J15*Assumptions!B46 -> -1951.2 | K15: =-'Volume & Funnel'!K15*Assumptions!B46 -> -2318.4 | L15: =-'Volume & Funnel'!L15*Assumptions!B46 -> -2754 | M15: =-'Volume & Funnel'!M15*Assumptions!B46 -> -3272.4 | O15: =-'Volume & Funnel'!O15*Assumptions!B46 -> -5050.8 | P15: =-'Volume & Funnel'!P15*Assumptions!B46 -> -5670 | Q15: =-'Volume & Funnel'!Q15*Assumptions!B46 -> -6364.8 | R15: =-'Volume & Funnel'!R15*Assumptions!B46 -> -7144.2 | S15: =-'Volume & Funnel'!S15*Assumptions!B46 -> -8017.2 | T15: =-'Volume & Funnel'!T15*Assumptions!B46 -> -9000 | U15: =-'Volume & Funnel'!U15*Assumptions!B46 -> -10101.6 | V15: =-'Volume & Funnel'!V15*Assumptions!B46 -> -11340 | W15: =-'Volume & Funnel'!W15*Assumptions!B46 -> -12727.8 | X15: =-'Volume & Funnel'!X15*Assumptions!B46 -> -14286.6 | Y15: =-'Volume & Funnel'!Y15*Assumptions!B46 -> -16036.2 | Z15: =-'Volume & Funnel'!Z15*Assumptions!B46 -> -18000 | AB15: =-'Volume & Funnel'!AB15*Assumptions!B46 -> -24271.2 | AC15: =-'Volume & Funnel'!AC15*Assumptions!B46 -> -25714.8 | AD15: =-'Volume & Funnel'!AD15*Assumptions!B46 -> -27243 | AE15: =-'Volume & Funnel'!AE15*Assumptions!B46 -> -28863 | AF15: =-'Volume & Funnel'!AF15*Assumptions!B46 -> -30580.2 | AG15: =-'Volume & Funnel'!AG15*Assumptions!B46 -> -32398.2 | AH15: =-'Volume & Funnel'!AH15*Assumptions!B46 -> -34324.2 | AI15: =-'Volume & Funnel'!AI15*Assumptions!B46 -> -36365.4 | AJ15: =-'Volume & Funnel'!AJ15*Assumptions!B46 -> -38529 | AK15: =-'Volume & Funnel'!AK15*Assumptions!B46 -> -40818.6 | AL15: =-'Volume & Funnel'!AL15*Assumptions!B46 -> -43236 | AM15: =-'Volume & Funnel'!AM15*Assumptions!B46 -> -43236 | AO15: =SUM(B15:M15) -> -18054 | AP15: =SUM(O15:Z15) -> -123739.2 | AQ15: =SUM(AB15:AM15) -> -405579.6
A16: TOTAL COST OF DELIVERY | B16: =SUM(B13:B15) -> -18713.4 | C16: =SUM(C13:C15) -> -19066.2 | D16: =SUM(D13:D15) -> -19491 | E16: =SUM(E13:E15) -> -20000.4 | F16: =SUM(F13:F15) -> -20605.2 | G16: =SUM(G13:G15) -> -21319.8 | H16: =SUM(H13:H15) -> -22169.4 | I16: =SUM(I13:I15) -> -23175.6 | ... M16: =SUM(M13:M15) -> -29513.4 | O16: =SUM(O13:O15) -> -53221.8 | P16: =SUM(P13:P15) -> -55623 | Q16: =SUM(Q13:Q15) -> -58324.8 | R16: =SUM(R13:R15) -> -61354.2 | S16: =SUM(S13:S15) -> -64747.2 | T16: =SUM(T13:T15) -> -68565 | U16: =SUM(U13:U15) -> -72843.6 | V16: =SUM(V13:V15) -> -77655 | ... Z16: =SUM(Z13:Z15) -> -103521 | AB16: =SUM(AB13:AB15) -> -153038.2 | AC16: =SUM(AC13:AC15) -> -158477.8 | AD16: =SUM(AD13:AD15) -> -164236 | AE16: =SUM(AE13:AE15) -> -170338 | AF16: =SUM(AF13:AF15) -> -176816.2 | AG16: =SUM(AG13:AG15) -> -183665.2 | AH16: =SUM(AH13:AH15) -> -190919.2 | AI16: =SUM(AI13:AI15) -> -198603.4 | ... AM16: =SUM(AM13:AM15) -> -224491 | AO16: =SUM(B16:M16) -> -271737 | AP16: =SUM(O16:Z16) -> -883888.2 | AQ16: =SUM(AB16:AM16) -> -2267223.6
A18: GROSS PROFIT | B18: =B10+B16 -> -13786.6 | C18: =C10+C16 -> -13206.342 | D18: =D10+D16 -> -12530.908 | E18: =E10+E16 -> -11729.687 | F18: =F10+F16 -> -10772.937 | G18: =G10+G16 -> -9639.9393 | H18: =H10+H16 -> -8287.5197 | I18: =I10+I16 -> -6686.9824 | ... M18: =M10+M16 -> 3358.6 | O18: =O10+O16 -> -2956.9369 | P18: =P10+P16 -> 796.37881 | Q18: =Q10+Q16 -> 5010.8364 | R18: =R10+R16 -> 9740.6109 | S18: =S10+S16 -> 15048.396 | T18: =T10+T16 -> 21001.4 | U18: =U10+U16 -> 27688.826 | V18: =V10+V16 -> 35195.758 | ... Z18: =Z10+Z16 -> 75611.8 | AB18: =AB10+AB16 -> 86583.206 | AC18: =AC10+AC16 -> 95389.049 | AD18: =AD10+AD16 -> 104727.63 | AE18: =AE10+AE16 -> 114623.35 | AF18: =AF10+AF16 -> 125088.64 | AG18: =AG10+AG16 -> 136190.52 | AH18: =AH10+AH16 -> 147960.06 | AI18: =AI10+AI16 -> 160423.92 | ... AM18: =AM10+AM16 -> 202368 | AO18: =SUM(B18:M18) -> -90426.88 | AP18: =SUM(O18:Z18) -> 347529.86 | AQ18: =SUM(AB18:AM18) -> 1736941.2
A19: Gross Margin % | B19: =IFERROR(B18/B10,0) -> -2.7982869 | C19: =IFERROR(C18/C10,0) -> -2.2536963 | D19: =IFERROR(D18/D10,0) -> -1.8003941 | E19: =IFERROR(E18/E10,0) -> -1.4182196 | F19: =IFERROR(F18/F10,0) -> -1.0956721 | G19: =IFERROR(G18/G10,0) -> -0.82534711 | H19: =IFERROR(H18/H10,0) -> -0.59700268 | I19: =IFERROR(I18/I10,0) -> -0.40555143 | ... M19: =IFERROR(M18/M10,0) -> 0.10217206 | O19: =IFERROR(O18/O10,0) -> -0.058827115 | P19: =IFERROR(P18/P10,0) -> 0.014115342 | Q19: =IFERROR(Q18/Q10,0) -> 0.079115593 | R19: =IFERROR(R18/R10,0) -> 0.13700875 | S19: =IFERROR(S18/S10,0) -> 0.1885868 | T19: =IFERROR(T18/T10,0) -> 0.23447855 | U19: =IFERROR(U18/U10,0) -> 0.27542184 | V19: =IFERROR(V18/V10,0) -> 0.31187879 | ... Z19: =IFERROR(Z18/Z10,0) -> 0.42209914 | AB19: =IFERROR(AB18/AB10,0) -> 0.36133335 | AC19: =IFERROR(AC18/AC10,0) -> 0.37574441 | AD19: =IFERROR(AD18/AD10,0) -> 0.3893747 | AE19: =IFERROR(AE18/AE10,0) -> 0.40224174 | AF19: =IFERROR(AF18/AF10,0) -> 0.41433135 | AG19: =IFERROR(AG18/AG10,0) -> 0.42578736 | AH19: =IFERROR(AH18/AH10,0) -> 0.43661587 | AI19: =IFERROR(AI18/AI10,0) -> 0.44682928 | ... AM19: =IFERROR(AM18/AM10,0) -> 0.47408629 | AO19: =IFERROR(AO18/AO10,0) -> -0.49874149 | AP19: =IFERROR(AP18/AP10,0) -> 0.28221923 | AQ19: =IFERROR(AQ18/AQ10,0) -> 0.43378365
A21: OPERATING EXPENSES
A22: Hub Operations Staff (QAR) | B22: =-Assumptions!B47 -> -12000 | C22: =-Assumptions!B47 -> -12000 | D22: =-Assumptions!B47 -> -12000 | E22: =-Assumptions!B47 -> -12000 | F22: =-Assumptions!B47 -> -12000 | G22: =-Assumptions!B47 -> -12000 | H22: =-Assumptions!B47 -> -12000 | I22: =-Assumptions!B47 -> -12000 | J22: =-Assumptions!B47 -> -12000 | K22: =-Assumptions!B47 -> -12000 | L22: =-Assumptions!B47 -> -12000 | M22: =-Assumptions!B47 -> -12000 | O22: =-Assumptions!B47 -> -12000 | P22: =-Assumptions!B47 -> -12000 | Q22: =-Assumptions!B47 -> -12000 | R22: =-Assumptions!B47 -> -12000 | S22: =-Assumptions!B47 -> -12000 | T22: =-Assumptions!B47 -> -12000 | U22: =-Assumptions!B47 -> -12000 | V22: =-Assumptions!B47 -> -12000 | W22: =-Assumptions!B47 -> -12000 | X22: =-Assumptions!B47 -> -12000 | Y22: =-Assumptions!B47 -> -12000 | Z22: =-Assumptions!B47 -> -12000 | AB22: =-Assumptions!B47 -> -12000 | AC22: =-Assumptions!B47 -> -12000 | AD22: =-Assumptions!B47 -> -12000 | AE22: =-Assumptions!B47 -> -12000 | AF22: =-Assumptions!B47 -> -12000 | AG22: =-Assumptions!B47 -> -12000 | AH22: =-Assumptions!B47 -> -12000 | AI22: =-Assumptions!B47 -> -12000 | AJ22: =-Assumptions!B47 -> -12000 | AK22: =-Assumptions!B47 -> -12000 | AL22: =-Assumptions!B47 -> -12000 | AM22: =-Assumptions!B47 -> -12000 | AO22: =SUM(B22:M22) -> -144000 | AP22: =SUM(O22:Z22) -> -144000 | AQ22: =SUM(AB22:AM22) -> -144000
A23: B2B Sales Executive (QAR) | B23: =-(Assumptions!B49/12) -> -6000 | C23: =-(Assumptions!B49/12) -> -6000 | D23: =-(Assumptions!B49/12) -> -6000 | E23: =-(Assumptions!B49/12) -> -6000 | F23: =-(Assumptions!B49/12) -> -6000 | G23: =-(Assumptions!B49/12) -> -6000 | H23: =-(Assumptions!B49/12) -> -6000 | I23: =-(Assumptions!B49/12) -> -6000 | J23: =-(Assumptions!B49/12) -> -6000 | K23: =-(Assumptions!B49/12) -> -6000 | L23: =-(Assumptions!B49/12) -> -6000 | M23: =-(Assumptions!B49/12) -> -6000 | O23: =-(Assumptions!B49/12) -> -6000 | P23: =-(Assumptions!B49/12) -> -6000 | Q23: =-(Assumptions!B49/12) -> -6000 | R23: =-(Assumptions!B49/12) -> -6000 | S23: =-(Assumptions!B49/12) -> -6000 | T23: =-(Assumptions!B49/12) -> -6000 | U23: =-(Assumptions!B49/12) -> -6000 | V23: =-(Assumptions!B49/12) -> -6000 | W23: =-(Assumptions!B49/12) -> -6000 | X23: =-(Assumptions!B49/12) -> -6000 | Y23: =-(Assumptions!B49/12) -> -6000 | Z23: =-(Assumptions!B49/12) -> -6000 | AB23: =-(Assumptions!B49/12) -> -6000 | AC23: =-(Assumptions!B49/12) -> -6000 | AD23: =-(Assumptions!B49/12) -> -6000 | AE23: =-(Assumptions!B49/12) -> -6000 | AF23: =-(Assumptions!B49/12) -> -6000 | AG23: =-(Assumptions!B49/12) -> -6000 | AH23: =-(Assumptions!B49/12) -> -6000 | AI23: =-(Assumptions!B49/12) -> -6000 | AJ23: =-(Assumptions!B49/12) -> -6000 | AK23: =-(Assumptions!B49/12) -> -6000 | AL23: =-(Assumptions!B49/12) -> -6000 | AM23: =-(Assumptions!B49/12) -> -6000 | AO23: =SUM(B23:M23) -> -72000 | AP23: =SUM(O23:Z23) -> -72000 | AQ23: =SUM(AB23:AM23) -> -72000
A24: TMS / Tracking Software (QAR) | B24: =-Assumptions!B48 -> -2500 | C24: =-Assumptions!B48 -> -2500 | D24: =-Assumptions!B48 -> -2500 | E24: =-Assumptions!B48 -> -2500 | F24: =-Assumptions!B48 -> -2500 | G24: =-Assumptions!B48 -> -2500 | H24: =-Assumptions!B48 -> -2500 | I24: =-Assumptions!B48 -> -2500 | J24: =-Assumptions!B48 -> -2500 | K24: =-Assumptions!B48 -> -2500 | L24: =-Assumptions!B48 -> -2500 | M24: =-Assumptions!B48 -> -2500 | O24: =-Assumptions!B48 -> -2500 | P24: =-Assumptions!B48 -> -2500 | Q24: =-Assumptions!B48 -> -2500 | R24: =-Assumptions!B48 -> -2500 | S24: =-Assumptions!B48 -> -2500 | T24: =-Assumptions!B48 -> -2500 | U24: =-Assumptions!B48 -> -2500 | V24: =-Assumptions!B48 -> -2500 | W24: =-Assumptions!B48 -> -2500 | X24: =-Assumptions!B48 -> -2500 | Y24: =-Assumptions!B48 -> -2500 | Z24: =-Assumptions!B48 -> -2500 | AB24: =-Assumptions!B48 -> -2500 | AC24: =-Assumptions!B48 -> -2500 | AD24: =-Assumptions!B48 -> -2500 | AE24: =-Assumptions!B48 -> -2500 | AF24: =-Assumptions!B48 -> -2500 | AG24: =-Assumptions!B48 -> -2500 | AH24: =-Assumptions!B48 -> -2500 | AI24: =-Assumptions!B48 -> -2500 | AJ24: =-Assumptions!B48 -> -2500 | AK24: =-Assumptions!B48 -> -2500 | AL24: =-Assumptions!B48 -> -2500 | AM24: =-Assumptions!B48 -> -2500 | AO24: =SUM(B24:M24) -> -30000 | AP24: =SUM(O24:Z24) -> -30000 | AQ24: =SUM(AB24:AM24) -> -30000
